Workbook
Name Периодные_даты: 'Общий капитал'!$A:$A
Name Сумма_за_периоды: 'Общий капитал'!$B:$B
Name SlicerCache_Table_1_Col_1: #N/A
Name SlicerCache_Table_1_Col_2: #N/A
Name SlicerCache_Table_2_Col_1: #N/A

Sheet Данные
A1: Категория | B1: Дата | C1: Сумма | D1: Тип
A2: А | B2: 45786 | C2: 114900 | D2: Актив
A3: Т | B3: 45786 | C3: 22066 | D3: Актив
A4: Бр.счет | B4: 45786 | C4: 293593 | D4: Инвестиция
A5: Вклад | B5: 45786 | C5: 257790 | D5: Подушка
A6: Сбер | B6: 45786 | C6: 27385 | D6: Актив
A7: ПИФ | B7: 45786 | C7: 66357 | D7: Инвестиция
A8: Доллары | B8: 45786 | C8: =769*83 -> 63827 | D8: Инвестиция
A9: ББ | B9: 45786 | C9: 16750 | D9: Актив
A10: А | B10: 45917 | C10: 31685 | D10: Актив
A11: Т | B11: 45917 | C11: 49418 | D11: Актив
A12: Бр.счет | B12: 45917 | C12: 375100 | D12: Инвестиция
A13: Вклад | B13: 45917 | C13: 152038 | D13: Подушка
A14: Сбер | B14: 45917 | C14: 138539 | D14: Актив
A15: ПИФ | B15: 45917 | C15: 99510 | D15: Инвестиция
A16: Доллары | B16: 45917 | C16: =775*83 -> 64325 | D16: Инвестиция
A17: ББ | B17: 45917 | C17: 10000 | D17: Актив
A18: А | B18: 45945 | C18: 28945 | D18: Актив
A19: Т | B19: 45945 | C19: 189834 | D19: Актив
A20: Бр.счет | B20: 45945 | C20: 350590 | D20: Инвестиция
A21: Вклад | B21: 45945 | C21: 0 | D21: Подушка
A22: Сбер | B22: 45945 | C22: 167653 | D22: Актив
A23: ПИФ | B23: 45945 | C23: 100704 | D23: Инвестиция
A24: Доллары | B24: 45945 | C24: 64000 | D24: Инвестиция
A25: ББ | B25: 45945 | C25: 23291 | D25: Актив
A26: А | B26: 45970 | C26: 20042 | D26: Актив
A27: Т | B27: 45970 | C27: =168181-150000 -> 18181 | D27: Актив
A28: Бр.счет | B28: 45970 | C28: 362795 | D28: Инвестиция
A29: Вклад | B29: 45970 | C29: 150000 | D29: Подушка
A30: Сбер | B30: 45970 | C30: 172700 | D30: Актив
A31: ПИФ | B31: 45970 | C31: 101733 | D31: Инвестиция
A32: Доллары | B32: 45970 | C32: 64000 | D32: Инвестиция
A33: ББ | B33: 45970 | C33: 21000 | D33: Актив
A34: А | B34: 46021 | C34: 45244 | D34: Актив
A35: Т | B35: 46021 | C35: 53462 | D35: Актив
A36: Бр.счет | B36: 46021 | C36: 454787 | D36: Инвестиция
A37: Вклад | B37: 46021 | C37: 100740 | D37: Подушка
A38: Сбер | B38: 46021 | C38: 197130 | D38: Актив
A39: ПИФ | B39: 46021 | C39: 103965 | D39: Инвестиция
... A104: Доллары | B104: 46276 | C104: 55000 | D104: Инвестиция
...

Sheet Общий капитал
C1: Прибыль\Убыль
C3: =B3-B2 -> 57947
C4: =B4-B3 -> 4402
C5: =B5-B4 -> -14566
C6: =B6-B5 -> 121877
C7: =B7-B6 -> -12678
C8: =B8-B7 -> 47465
C9: =B9-B8 -> -48725
C10: =B10-B9 -> -43980
C11: =B11-B10 -> 13190
C12: =B12-B11 -> 36360
C13: =B13-B12 -> -9628
C14: =B14-B13 -> 18748
... C19: =B19-B18 -> 0

Sheet Капитал по типам

Sheet Dashboards
B2: Общий капитал на последнюю дату | C2: =Calculating!C2 -> 1071050
B4: Средний баланс по датам за период | C4: =Calculating!C4 -> 990047.57
B6: Минимальная сумма | C6: =Calculating!C8 -> 862668
B8: Максимальная сумма | C8: =Calculating!C10 -> 1071050
B10: Прирост за все время | C10: =Calculating!C12 -> 208382
B12: Рост за все время (МАЙ25 - СЕН26) | C12: =Calculating!C14 -> 0.24155527
B14: Средний прирост за период (CAGR) | C14: =Calculating!C16 -> 0.014528855
B16: Прогноз капитала через год | C16: =Calculating!C18 -> 1329767.8

Sheet Calculating
B2: Общий капитал на последнюю дату | C2: =SUMIFS('Общий капитал'!B2:B1000, 'Общий капитал'!A2:A1000, MAX('Общий капитал'!A2:A1000)) -> 1071050
B4: Средний баланс по датам за период | C4: =AVERAGE('Общий капитал'!B2:B1000) -> 990047.57
B6: Количество точек данных (дат) | C6: =COUNT('Данные'!B2:B952)/8 -> 14
B8: Минимальная сумма | C8: =MIN(Сумма_за_периоды) -> 862668
B10: Максимальная сумма | C10: =MAX(Сумма_за_периоды) -> 1071050
B12: Прирост за все время | C12: ='Общий капитал'!B15-'Общий капитал'!B2 -> 208382
B14: Рост за все время (МАЙ25 - СЕН26) | C14: =('Общий капитал'!B15/'Общий капитал'!B2)-1 -> 0.24155527
B16: Средний прирост за период (CAGR) | C16: =('Общий капитал'!B15/'Общий капитал'!B2)^(1/COUNTA('Общий капитал'!A:A))-1 -> 0.014528855
B18: Прогноз капитала через год | C18: =C2*(1+C14) -> 1329767.8
